Workbook

Sheet Data
A1: InvoiceNo | B1: StockCode | C1: Description | D1: Quantity | E1: InvoiceDate | F1: UnitPrice | G1: CustomerID | H1: Country | I1: LineTotal | J1: Valid | K1: UK_FirstCustomerRow
A2: 536366 | B2: 10029 | C2: DOORMAT | D2: 4 | E2: 40513.355 | F2: 3.33 | G2: 17203 | H2: United Kingdom | I2: =D2*F2 -> 13.32 | J2: =IF(AND(LEFT(A2,1)<>"C",D2>0,F2>0),1,0) -> 1 | K2: =IF(AND(H2="United Kingdom",G2<>"",COUNTIFS($G$2:G2,G2,$H$2:H2,"United Kingdom")=1),1,0) -> 1
A3: 536366 | B3: 10016 | C3: NOTEBOOK | D3: 2 | E3: 40513.355 | F3: 3.18 | G3: 17203 | H3: United Kingdom | I3: =D3*F3 -> 6.36 | J3: =IF(AND(LEFT(A3,1)<>"C",D3>0,F3>0),1,0) -> 1 | K3: =IF(AND(H3="United Kingdom",G3<>"",COUNTIFS($G$2:G3,G3,$H$2:H3,"United Kingdom")=1),1,0) -> 0
A4: 536366 | B4: 10025 | C4: TRAY | D4: 8 | E4: 40513.355 | F4: 1.92 | G4: 17203 | H4: United Kingdom | I4: =D4*F4 -> 15.36 | J4: =IF(AND(LEFT(A4,1)<>"C",D4>0,F4>0),1,0) -> 1 | K4: =IF(AND(H4="United Kingdom",G4<>"",COUNTIFS($G$2:G4,G4,$H$2:H4,"United Kingdom")=1),1,0) -> 0
A5: 536365 | B5: 10025 | C5: TRAY | D5: 6 | E5: 40513.691 | F5: 1.92 | H5: United Kingdom | I5: =D5*F5 -> 11.52 | J5: =IF(AND(LEFT(A5,1)<>"C",D5>0,F5>0),1,0) -> 1 | K5: =IF(AND(H5="United Kingdom",G5<>"",COUNTIFS($G$2:G5,G5,$H$2:H5,"United Kingdom")=1),1,0) -> 0
A6: 536365 | B6: 10011 | C6: LUNCH BAG | D6: 16 | E6: 40513.691 | F6: 4.24 | H6: United Kingdom | I6: =D6*F6 -> 67.84 | J6: =IF(AND(LEFT(A6,1)<>"C",D6>0,F6>0),1,0) -> 1 | K6: =IF(AND(H6="United Kingdom",G6<>"",COUNTIFS($G$2:G6,G6,$H$2:H6,"United Kingdom")=1),1,0) -> 0
A7: 536365 | B7: 10027 | C7: CAKE STAND | D7: 4 | E7: 40513.691 | F7: 3.18 | H7: United Kingdom | I7: =D7*F7 -> 12.72 | J7: =IF(AND(LEFT(A7,1)<>"C",D7>0,F7>0),1,0) -> 1 | K7: =IF(AND(H7="United Kingdom",G7<>"",COUNTIFS($G$2:G7,G7,$H$2:H7,"United Kingdom")=1),1,0) -> 0
A8: 536367 | B8: 10025 | C8: TRAY | D8: 6 | E8: 40514.436 | F8: 1.92 | H8: United Kingdom | I8: =D8*F8 -> 11.52 | J8: =IF(AND(LEFT(A8,1)<>"C",D8>0,F8>0),1,0) -> 1 | K8: =IF(AND(H8="United Kingdom",G8<>"",COUNTIFS($G$2:G8,G8,$H$2:H8,"United Kingdom")=1),1,0) -> 0
A9: 536367 | B9: 10023 | C9: MIRROR | D9: 6 | E9: 40514.436 | F9: 2.21 | H9: United Kingdom | I9: =D9*F9 -> 13.26 | J9: =IF(AND(LEFT(A9,1)<>"C",D9>0,F9>0),1,0) -> 1 | K9: =IF(AND(H9="United Kingdom",G9<>"",COUNTIFS($G$2:G9,G9,$H$2:H9,"United Kingdom")=1),1,0) -> 0
A10: 536367 | B10: 10010 | C10: BIRD HOUSE | D10: 24 | E10: 40514.436 | F10: 4.55 | H10: United Kingdom | I10: =D10*F10 -> 109.2 | J10: =IF(AND(LEFT(A10,1)<>"C",D10>0,F10>0),1,0) -> 1 | K10: =IF(AND(H10="United Kingdom",G10<>"",COUNTIFS($G$2:G10,G10,$H$2:H10,"United Kingdom")=1),1,0) -> 0
A11: 536367 | B11: 10022 | C11: PICNIC BASKET | D11: 1 | E11: 40514.436 | F11: 5.79 | H11: United Kingdom | I11: =D11*F11 -> 5.79 | J11: =IF(AND(LEFT(A11,1)<>"C",D11>0,F11>0),1,0) -> 1 | K11: =IF(AND(H11="United Kingdom",G11<>"",COUNTIFS($G$2:G11,G11,$H$2:H11,"United Kingdom")=1),1,0) -> 0
A12: 536367 | B12: 10027 | C12: CAKE STAND | D12: 8 | E12: 40514.436 | F12: 3.18 | H12: United Kingdom | I12: =D12*F12 -> 25.44 | J12: =IF(AND(LEFT(A12,1)<>"C",D12>0,F12>0),1,0) -> 1 | K12: =IF(AND(H12="United Kingdom",G12<>"",COUNTIFS($G$2:G12,G12,$H$2:H12,"United Kingdom")=1),1,0) -> 0
A13: 536370 | B13: 10001 | C13: CERAMIC MUG | D13: 4 | E13: 40515.537 | F13: 1.19 | G13: 16661 | H13: United Kingdom | I13: =D13*F13 -> 4.76 | J13: =IF(AND(LEFT(A13,1)<>"C",D13>0,F13>0),1,0) -> 1 | K13: =IF(AND(H13="United Kingdom",G13<>"",COUNTIFS($G$2:G13,G13,$H$2:H13,"United Kingdom")=1),1,0) -> 1
A14: 536370 | B14: 10019 | C14: ADVENT CALENDAR | D14: 2 | E14: 40515.537 | F14: 2.38 | G14: 16661 | H14: United Kingdom | I14: =D14*F14 -> 4.76 | J14: =IF(AND(LEFT(A14,1)<>"C",D14>0,F14>0),1,0) -> 1 | K14: =IF(AND(H14="United Kingdom",G14<>"",COUNTIFS($G$2:G14,G14,$H$2:H14,"United Kingdom")=1),1,0) -> 0
A15: 536368 | B15: 10025 | C15: TRAY | D15: 8 | E15: 40515.635 | F15: 1.92 | G15: 13924 | H15: United Kingdom | I15: =D15*F15 -> 15.36 | J15: =IF(AND(LEFT(A15,1)<>"C",D15>0,F15>0),1,0) -> 1 | K15: =IF(AND(H15="United Kingdom",G15<>"",COUNTIFS($G$2:G15,G15,$H$2:H15,"United Kingdom")=1),1,0) -> 1
A16: 536368 | B16: 10024 | C16: VASE | D16: 4 | E16: 40515.635 | F16: 1.82 | G16: 13924 | H16: United Kingdom | I16: =D16*F16 -> 7.28 | J16: =IF(AND(LEFT(A16,1)<>"C",D16>0,F16>0),1,0) -> 1 | K16: =IF(AND(H16="United Kingdom",G16<>"",COUNTIFS($G$2:G16,G16,$H$2:H16,"United Kingdom")=1),1,0) -> 0
A17: 536368 | B17: 10016 | C17: NOTEBOOK | D17: 1 | E17: 40515.635 | F17: 3.18 | G17: 13924 | H17: United Kingdom | I17: =D17*F17 -> 3.18 | J17: =IF(AND(LEFT(A17,1)<>"C",D17>0,F17>0),1,0) -> 1 | K17: =IF(AND(H17="United Kingdom",G17<>"",COUNTIFS($G$2:G17,G17,$H$2:H17,"United Kingdom")=1),1,0) -> 0
A18: 536368 | B18: 10012 | C18: WALL CLOCK | D18: 3 | E18: 40515.635 | F18: 2.58 | G18: 13924 | H18: United Kingdom | I18: =D18*F18 -> 7.74 | J18: =IF(AND(LEFT(A18,1)<>"C",D18>0,F18>0),1,0) -> 1 | K18: =IF(AND(H18="United Kingdom",G18<>"",COUNTIFS($G$2:G18,G18,$H$2:H18,"United Kingdom")=1),1,0) -> 0
A19: 536368 | B19: 10028 | C19: LANTERN | D19: 1 | E19: 40515.635 | F19: 3.28 | G19: 13924 | H19: United Kingdom | I19: =D19*F19 -> 3.28 | J19: =IF(AND(LEFT(A19,1)<>"C",D19>0,F19>0),1,0) -> 1 | K19: =IF(AND(H19="United Kingdom",G19<>"",COUNTIFS($G$2:G19,G19,$H$2:H19,"United Kingdom")=1),1,0) -> 0
A20: 536368 | B20: 10015 | C20: COASTER SET | D20: 2 | E20: 40515.635 | F20: 1.35 | G20: 13924 | H20: United Kingdom | I20: =D20*F20 -> 2.7 | J20: =IF(AND(LEFT(A20,1)<>"C",D20>0,F20>0),1,0) -> 1 | K20: =IF(AND(H20="United Kingdom",G20<>"",COUNTIFS($G$2:G20,G20,$H$2:H20,"United Kingdom")=1),1,0) -> 0
A21: 536368 | B21: 10018 | C21: CHRISTMAS BAUBLE | D21: 1 | E21: 40515.635 | F21: 4.55 | G21: 13924 | H21: United Kingdom | I21: =D21*F21 -> 4.55 | J21: =IF(AND(LEFT(A21,1)<>"C",D21>0,F21>0),1,0) -> 1 | K21: =IF(AND(H21="United Kingdom",G21<>"",COUNTIFS($G$2:G21,G21,$H$2:H21,"United Kingdom")=1),1,0) -> 0
A22: 536369 | B22: 10009 | C22: PHOTO FRAME | D22: 16 | E22: 40515.803 | F22: 1.35 | G22: 14264 | H22: United Kingdom | I22: =D22*F22 -> 21.6 | J22: =IF(AND(LEFT(A22,1)<>"C",D22>0,F22>0),1,0) -> 1 | K22: =IF(AND(H22="United Kingdom",G22<>"",COUNTIFS($G$2:G22,G22,$H$2:H22,"United Kingdom")=1),1,0) -> 1
A23: 536369 | B23: 10013 | C23: DOOR SIGN | D23: 1 | E23: 40515.803 | F23: 5.41 | G23: 14264 | H23: United Kingdom | I23: =D23*F23 -> 5.41 | J23: =IF(AND(LEFT(A23,1)<>"C",D23>0,F23>0),1,0) -> 1 | K23: =IF(AND(H23="United Kingdom",G23<>"",COUNTIFS($G$2:G23,G23,$H$2:H23,"United Kingdom")=1),1,0) -> 0
A24: 536369 | B24: 10002 | C24: CANDLE HOLDER | D24: 8 | E24: 40515.803 | F24: 4.16 | G24: 14264 | H24: United Kingdom | I24: =D24*F24 -> 33.28 | J24: =IF(AND(LEFT(A24,1)<>"C",D24>0,F24>0),1,0) -> 1 | K24: =IF(AND(H24="United Kingdom",G24<>"",COUNTIFS($G$2:G24,G24,$H$2:H24,"United Kingdom")=1),1,0) -> 0
... A51: 536378 | B51: 10021 | C51: HOT WATER BOTTLE | D51: 2 | E51: 40521.422 | F51: 1.53 | G51: 13045 | H51: United Kingdom | I51: =D51*F51 -> 3.06 | J51: =IF(AND(LEFT(A51,1)<>"C",D51>0,F51>0),1,0) -> 1 | K51: =IF(AND(H51="United Kingdom",G51<>"",COUNTIFS($G$2:G51,G51,$H$2:H51,"United Kingdom")=1),1,0) -> 1
A52: 536377 | B52: 10024 | C52: VASE | D52: 4 | E52: 40521.465 | F52: 1.82 | H52: United Kingdom | I52: =D52*F52 -> 7.28 | J52: =IF(AND(LEFT(A52,1)<>"C",D52>0,F52>0),1,0) -> 1 | K52: =IF(AND(H52="United Kingdom",G52<>"",COUNTIFS($G$2:G52,G52,$H$2:H52,"United Kingdom")=1),1,0) -> 0
A53: 536377 | B53: 10018 | C53: CHRISTMAS BAUBLE | D53: 12 | E53: 40521.465 | F53: 4.55 | H53: United Kingdom | I53: =D53*F53 -> 54.6 | J53: =IF(AND(LEFT(A53,1)<>"C",D53>0,F53>0),1,0) -> 1 | K53: =IF(AND(H53="United Kingdom",G53<>"",COUNTIFS($G$2:G53,G53,$H$2:H53,"United Kingdom")=1),1,0) -> 0
A54: 536377 | B54: 10019 | C54: ADVENT CALENDAR | D54: 6 | E54: 40521.465 | F54: 2.38 | H54: United Kingdom | I54: =D54*F54 -> 14.28 | J54: =IF(AND(LEFT(A54,1)<>"C",D54>0,F54>0),1,0) -> 1 | K54: =IF(AND(H54="United Kingdom",G54<>"",COUNTIFS($G$2:G54,G54,$H$2:H54,"United Kingdom")=1),1,0) -> 0
A55: 536377 | B55: 10011 | C55: LUNCH BAG | D55: 6 | E55: 40521.465 | F55: 4.24 | H55: United Kingdom | I55: =D55*F55 -> 25.44 | J55: =IF(AND(LEFT(A55,1)<>"C",D55>0,F55>0),1,0) -> 1 | K55: =IF(AND(H55="United Kingdom",G55<>"",COUNTIFS($G$2:G55,G55,$H$2:H55,"United Kingdom")=1),1,0) -> 0
A56: 536377 | B56: 10013 | C56: DOOR SIGN | D56: 3 | E56: 40521.465 | F56: 5.41 | H56: United Kingdom | I56: =D56*F56 -> 16.23 | J56: =IF(AND(LEFT(A56,1)<>"C",D56>0,F56>0),1,0) -> 1 | K56: =IF(AND(H56="United Kingdom",G56<>"",COUNTIFS($G$2:G56,G56,$H$2:H56,"United Kingdom")=1),1,0) -> 0
A57: 536377 | B57: 10020 | C57: KEY RING | D57: 6 | E57: 40521.465 | F57: 2.16 | H57: United Kingdom | I57: =D57*F57 -> 12.96 | J57: =IF(AND(LEFT(A57,1)<>"C",D57>0,F57>0),1,0) -> 1 | K57: =IF(AND(H57="United Kingdom",G57<>"",COUNTIFS($G$2:G57,G57,$H$2:H57,"United Kingdom")=1),1,0) -> 0
A58: 536380 | B58: 10029 | C58: DOORMAT | D58: 3 | E58: 40521.642 | F58: 3.33 | G58: 17650 | H58: Germany | I58: =D58*F58 -> 9.99 | J58: =IF(AND(LEFT(A58,1)<>"C",D58>0,F58>0),1,0) -> 1 | K58: =IF(AND(H58="United Kingdom",G58<>"",COUNTIFS($G$2:G58,G58,$H$2:H58,"United Kingdom")=1),1,0) -> 0
A59: 536380 | B59: 10005 | C59: GLASS JAR | D59: 9 | E59: 40521.642 | F59: 0.99 | G59: 17650 | H59: Germany | I59: =D59*F59 -> 8.91 | J59: =IF(AND(LEFT(A59,1)<>"C",D59>0,F59>0),1,0) -> 1 | K59: =IF(AND(H59="United Kingdom",G59<>"",COUNTIFS($G$2:G59,G59,$H$2:H59,"United Kingdom")=1),1,0) -> 0
A60: 536379 | B60: 10028 | C60: LANTERN | D60: 1 | E60: 40521.756 | F60: 3.28 | G60: 14074 | H60: United Kingdom | I60: =D60*F60 -> 3.28 | J60: =IF(AND(LEFT(A60,1)<>"C",D60>0,F60>0),1,0) -> 1 | K60: =IF(AND(H60="United Kingdom",G60<>"",COUNTIFS($G$2:G60,G60,$H$2:H60,"United Kingdom")=1),1,0) -> 1
A61: 536379 | B61: 10019 | C61: ADVENT CALENDAR | D61: 2 | E61: 40521.756 | F61: 2.38 | G61: 14074 | H61: United Kingdom | I61: =D61*F61 -> 4.76 | J61: =IF(AND(LEFT(A61,1)<>"C",D61>0,F61>0),1,0) -> 1 | K61: =IF(AND(H61="United Kingdom",G61<>"",COUNTIFS($G$2:G61,G61,$H$2:H61,"United Kingdom")=1),1,0) -> 0
A62: 536379 | B62: 10022 | C62: PICNIC BASKET | D62: 8 | E62: 40521.756 | F62: 5.79 | G62: 14074 | H62: United Kingdom | I62: =D62*F62 -> 46.32 | J62: =IF(AND(LEFT(A62,1)<>"C",D62>0,F62>0),1,0) -> 1 | K62: =IF(AND(H62="United Kingdom",G62<>"",COUNTIFS($G$2:G62,G62,$H$2:H62,"United Kingdom")=1),1,0) -> 0
A63: 536379 | B63: 10021 | C63: HOT WATER BOTTLE | D63: 1 | E63: 40521.756 | F63: 1.53 | G63: 14074 | H63: United Kingdom | I63: =D63*F63 -> 1.53 | J63: =IF(AND(LEFT(A63,1)<>"C",D63>0,F63>0),1,0) -> 1 | K63: =IF(AND(H63="United Kingdom",G63<>"",COUNTIFS($G$2:G63,G63,$H$2:H63,"United Kingdom")=1),1,0) -> 0
A64: 536379 | B64: 10004 | C64: PAPER BUNTING | D64: 12 | E64: 40521.756 | F64: 0.63 | G64: 14074 | H64: United Kingdom | I64: =D64*F64 -> 7.56 | J64: =IF(AND(LEFT(A64,1)<>"C",D64>0,F64>0),1,0) -> 1 | K64: =IF(AND(H64="United Kingdom",G64<>"",COUNTIFS($G$2:G64,G64,$H$2:H64,"United Kingdom")=1),1,0) -> 0
A65: 536379 | B65: 10029 | C65: DOORMAT | D65: 8 | E65: 40521.756 | F65: 3.33 | G65: 14074 | H65: United Kingdom | I65: =D65*F65 -> 26.64 | J65: =IF(AND(LEFT(A65,1)<>"C",D65>0,F65>0),1,0) -> 1 | K65: =IF(AND(H65="United Kingdom",G65<>"",COUNTIFS($G$2:G65,G65,$H$2:H65,"United Kingdom")=1),1,0) -> 0
A66: 536381 | B66: 10022 | C66: PICNIC BASKET | D66: 16 | E66: 40522.423 | F66: 5.79 | G66: 17892 | H66: United Kingdom | I66: =D66*F66 -> 92.64 | J66: =IF(AND(LEFT(A66,1)<>"C",D66>0,F66>0),1,0) -> 1 | K66: =IF(AND(H66="United Kingdom",G66<>"",COUNTIFS($G$2:G66,G66,$H$2:H66,"United Kingdom")=1),1,0) -> 1
...

Sheet Task1_UK_Filter
A1: Task 1: United Kingdom transactions and unique customers
A2: On the Data sheet use the Country filter arrow and tick only United Kingdom (Data > Filter).
A4: Total transaction rows in data | B4: =COUNTA(Data!$A$2:$A$3990) -> 3989
A5: UK transaction rows | B5: =COUNTIF(Data!$H$2:$H$3990,"United Kingdom") -> 3194
A6: Rows currently visible after filtering (SUBTOTAL) | B6: =SUBTOTAL(103,Data!$A$2:$A$3990) -> 3989
A7: UK rows with a missing CustomerID | B7: =COUNTIFS(Data!$H$2:$H$3990,"United Kingdom",Data!$G$2:$G$3990,"") -> 249
A8: Unique CustomerIDs who purchased from the UK | B8: =SUM(Data!$K$2:$K$3990) -> 145
A10: How the unique count works: column K on the Data sheet marks the first row of each UK CustomerID with 1, so the sum is the number of distinct customers. (Blank CustomerIDs are not counted.)

Sheet Task2_Sales_by_Country
A1: Task 2: Total sales (Quantity x UnitPrice) by country
A2: This table is the formula version of a PivotTable (Rows = Country, Values = Sum of LineTotal). Valid sales only (no cancellations).
A4: Country | B4: Total sales | C4: Rank | D4: Share of sales
A5: United Kingdom | B5: =SUMIFS(Data!$I$2:$I$3990,Data!$H$2:$H$3990,A5,Data!$J$2:$J$3990,1) -> 207505.63 | C5: =RANK(B5,$B$5:$B$13) -> 1 | D5: =B5/SUM($B$5:$B$13) -> 0.66105623
A6: Germany | B6: =SUMIFS(Data!$I$2:$I$3990,Data!$H$2:$H$3990,A6,Data!$J$2:$J$3990,1) -> 47103.16 | C6: =RANK(B6,$B$5:$B$13) -> 2 | D6: =B6/SUM($B$5:$B$13) -> 0.1500578
A7: EIRE | B7: =SUMIFS(Data!$I$2:$I$3990,Data!$H$2:$H$3990,A7,Data!$J$2:$J$3990,1) -> 18306.74 | C7: =RANK(B7,$B$5:$B$13) -> 3 | D7: =B7/SUM($B$5:$B$13) -> 0.058320271
A8: Australia | B8: =SUMIFS(Data!$I$2:$I$3990,Data!$H$2:$H$3990,A8,Data!$J$2:$J$3990,1) -> 15825.9 | C8: =RANK(B8,$B$5:$B$13) -> 4 | D8: =B8/SUM($B$5:$B$13) -> 0.050416993
A9: Netherlands | B9: =SUMIFS(Data!$I$2:$I$3990,Data!$H$2:$H$3990,A9,Data!$J$2:$J$3990,1) -> 8421.42 | C9: =RANK(B9,$B$5:$B$13) -> 5 | D9: =B9/SUM($B$5:$B$13) -> 0.026828343
A10: France | B10: =SUMIFS(Data!$I$2:$I$3990,Data!$H$2:$H$3990,A10,Data!$J$2:$J$3990,1) -> 5988.97 | C10: =RANK(B10,$B$5:$B$13) -> 6 | D10: =B10/SUM($B$5:$B$13) -> 0.019079222
A11: Switzerland | B11: =SUMIFS(Data!$I$2:$I$3990,Data!$H$2:$H$3990,A11,Data!$J$2:$J$3990,1) -> 5773.04 | C11: =RANK(B11,$B$5:$B$13) -> 7 | D11: =B11/SUM($B$5:$B$13) -> 0.018391328
A12: Belgium | B12: =SUMIFS(Data!$I$2:$I$3990,Data!$H$2:$H$3990,A12,Data!$J$2:$J$3990,1) -> 4804 | C12: =RANK(B12,$B$5:$B$13) -> 8 | D12: =B12/SUM($B$5:$B$13) -> 0.015304231
A13: Spain | B13: =SUMIFS(Data!$I$2:$I$3990,Data!$H$2:$H$3990,A13,Data!$J$2:$J$3990,1) -> 171.26 | C13: =RANK(B13,$B$5:$B$13) -> 9 | D13: =B13/SUM($B$5:$B$13) -> 0.00054558756
A14: Total | B14: =SUM(B5:B13) -> 313900.12
A17: Top 3 countries by total sales
A18: 1st | B18: =INDEX($A$5:$A$13,MATCH(1,$C$5:$C$13,0)) -> United Kingdom
A19: 2nd | B19: =INDEX($A$5:$A$13,MATCH(2,$C$5:$C$13,0)) -> Germany
A20: 3rd | B20: =INDEX($A$5:$A$13,MATCH(3,$C$5:$C$13,0)) -> EIRE

Sheet Task3_Order_Value
A1: Task 3: Order value per InvoiceNo (highlight above 10,000)
A3: InvoiceNo | B3: Country | C3: Order value | D3: Flag | F3: Summary
A4: 536365 | B4: =INDEX(Data!$H$2:$H$3990,MATCH(A4,Data!$A$2:$A$3990,0)) -> United Kingdom | C4: =SUMIFS(Data!$I$2:$I$3990,Data!$A$2:$A$3990,A4,Data!$J$2:$J$3990,1) -> 92.08 | D4: =IF(C4>10000,"HIGH VALUE","") | F4: Number of invoices | G4: =COUNTA(A4:A723) -> 720
A5: 536366 | B5: =INDEX(Data!$H$2:$H$3990,MATCH(A5,Data!$A$2:$A$3990,0)) -> United Kingdom | C5: =SUMIFS(Data!$I$2:$I$3990,Data!$A$2:$A$3990,A5,Data!$J$2:$J$3990,1) -> 35.04 | D5: =IF(C5>10000,"HIGH VALUE","") | F5: Average order value | G5: =AVERAGE(C4:C723) -> 435.97239
A6: 536367 | B6: =INDEX(Data!$H$2:$H$3990,MATCH(A6,Data!$A$2:$A$3990,0)) -> United Kingdom | C6: =SUMIFS(Data!$I$2:$I$3990,Data!$A$2:$A$3990,A6,Data!$J$2:$J$3990,1) -> 165.21 | D6: =IF(C6>10000,"HIGH VALUE","") | F6: Median order value | G6: =MEDIAN(C4:C723) -> 79.81
A7: 536368 | B7: =INDEX(Data!$H$2:$H$3990,MATCH(A7,Data!$A$2:$A$3990,0)) -> United Kingdom | C7: =SUMIFS(Data!$I$2:$I$3990,Data!$A$2:$A$3990,A7,Data!$J$2:$J$3990,1) -> 44.09 | D7: =IF(C7>10000,"HIGH VALUE","") | F7: Largest order | G7: =MAX(C4:C723) -> 13671.14
A8: 536369 | B8: =INDEX(Data!$H$2:$H$3990,MATCH(A8,Data!$A$2:$A$3990,0)) -> United Kingdom | C8: =SUMIFS(Data!$I$2:$I$3990,Data!$A$2:$A$3990,A8,Data!$J$2:$J$3990,1) -> 63.26 | D8: =IF(C8>10000,"HIGH VALUE","") | F8: Invoices above 10,000 | G8: =COUNTIF(C4:C723,">10000") -> 3
A9: 536370 | B9: =INDEX(Data!$H$2:$H$3990,MATCH(A9,Data!$A$2:$A$3990,0)) -> United Kingdom | C9: =SUMIFS(Data!$I$2:$I$3990,Data!$A$2:$A$3990,A9,Data!$J$2:$J$3990,1) -> 9.52 | D9: =IF(C9>10000,"HIGH VALUE","") | F9: Threshold | G9: 10000
A10: 536371 | B10: =INDEX(Data!$H$2:$H$3990,MATCH(A10,Data!$A$2:$A$3990,0)) -> Germany | C10: =SUMIFS(Data!$I$2:$I$3990,Data!$A$2:$A$3990,A10,Data!$J$2:$J$3990,1) -> 178.6 | D10: =IF(C10>10000,"HIGH VALUE","")
A11: 536372 | B11: =INDEX(Data!$H$2:$H$3990,MATCH(A11,Data!$A$2:$A$3990,0)) -> Germany | C11: =SUMIFS(Data!$I$2:$I$3990,Data!$A$2:$A$3990,A11,Data!$J$2:$J$3990,1) -> 173.23 | D11: =IF(C11>10000,"HIGH VALUE","") | F11: Invoice list is static; in Excel you can build it with Remove Duplicates or =UNIQUE().
A12: 536373 | B12: =INDEX(Data!$H$2:$H$3990,MATCH(A12,Data!$A$2:$A$3990,0)) -> United Kingdom | C12: =SUMIFS(Data!$I$2:$I$3990,Data!$A$2:$A$3990,A12,Data!$J$2:$J$3990,1) -> 3.18 | D12: =IF(C12>10000,"HIGH VALUE","")
A13: 536374 | B13: =INDEX(Data!$H$2:$H$3990,MATCH(A13,Data!$A$2:$A$3990,0)) -> United Kingdom | C13: =SUMIFS(Data!$I$2:$I$3990,Data!$A$2:$A$3990,A13,Data!$J$2:$J$3990,1) -> 48 | D13: =IF(C13>10000,"HIGH VALUE","")
A14: 536375 | B14: =INDEX(Data!$H$2:$H$3990,MATCH(A14,Data!$A$2:$A$3990,0)) -> United Kingdom | C14: =SUMIFS(Data!$I$2:$I$3990,Data!$A$2:$A$3990,A14,Data!$J$2:$J$3990,1) -> 7.11 | D14: =IF(C14>10000,"HIGH VALUE","")
A15: 536376 | B15: =INDEX(Data!$H$2:$H$3990,MATCH(A15,Data!$A$2:$A$3990,0)) -> United Kingdom | C15: =SUMIFS(Data!$I$2:$I$3990,Data!$A$2:$A$3990,A15,Data!$J$2:$J$3990,1) -> 40.11 | D15: =IF(C15>10000,"HIGH VALUE","")
A16: 536377 | B16: =INDEX(Data!$H$2:$H$3990,MATCH(A16,Data!$A$2:$A$3990,0)) -> United Kingdom | C16: =SUMIFS(Data!$I$2:$I$3990,Data!$A$2:$A$3990,A16,Data!$J$2:$J$3990,1) -> 130.79 | D16: =IF(C16>10000,"HIGH VALUE","")
A17: 536378 | B17: =INDEX(Data!$H$2:$H$3990,MATCH(A17,Data!$A$2:$A$3990,0)) -> United Kingdom | C17: =SUMIFS(Data!$I$2:$I$3990,Data!$A$2:$A$3990,A17,Data!$J$2:$J$3990,1) -> 3.06 | D17: =IF(C17>10000,"HIGH VALUE","")
A18: 536379 | B18: =INDEX(Data!$H$2:$H$3990,MATCH(A18,Data!$A$2:$A$3990,0)) -> United Kingdom | C18: =SUMIFS(Data!$I$2:$I$3990,Data!$A$2:$A$3990,A18,Data!$J$2:$J$3990,1) -> 90.09 | D18: =IF(C18>10000,"HIGH VALUE","")
A19: 536380 | B19: =INDEX(Data!$H$2:$H$3990,MATCH(A19,Data!$A$2:$A$3990,0)) -> Germany | C19: =SUMIFS(Data!$I$2:$I$3990,Data!$A$2:$A$3990,A19,Data!$J$2:$J$3990,1) -> 18.9 | D19: =IF(C19>10000,"HIGH VALUE","")
A20: 536381 | B20: =INDEX(Data!$H$2:$H$3990,MATCH(A20,Data!$A$2:$A$3990,0)) -> United Kingdom | C20: =SUMIFS(Data!$I$2:$I$3990,Data!$A$2:$A$3990,A20,Data!$J$2:$J$3990,1) -> 181.75 | D20: =IF(C20>10000,"HIGH VALUE","")
A21: 536382 | B21: =INDEX(Data!$H$2:$H$3990,MATCH(A21,Data!$A$2:$A$3990,0)) -> United Kingdom | C21: =SUMIFS(Data!$I$2:$I$3990,Data!$A$2:$A$3990,A21,Data!$J$2:$J$3990,1) -> 110.16 | D21: =IF(C21>10000,"HIGH VALUE","")
A22: 536383 | B22: =INDEX(Data!$H$2:$H$3990,MATCH(A22,Data!$A$2:$A$3990,0)) -> Switzerland | C22: =SUMIFS(Data!$I$2:$I$3990,Data!$A$2:$A$3990,A22,Data!$J$2:$J$3990,1) -> 46.8 | D22: =IF(C22>10000,"HIGH VALUE","")
A23: 536384 | B23: =INDEX(Data!$H$2:$H$3990,MATCH(A23,Data!$A$2:$A$3990,0)) -> United Kingdom | C23: =SUMIFS(Data!$I$2:$I$3990,Data!$A$2:$A$3990,A23,Data!$J$2:$J$3990,1) -> 13 | D23: =IF(C23>10000,"HIGH VALUE","")
... A723: 537084 | B723: =INDEX(Data!$H$2:$H$3990,MATCH(A723,Data!$A$2:$A$3990,0)) -> United Kingdom | C723: =SUMIFS(Data!$I$2:$I$3990,Data!$A$2:$A$3990,A723,Data!$J$2:$J$3990,1) -> 129.84 | D723: =IF(C723>10000,"HIGH VALUE","")

Sheet Task4_TTest
A1: Task 4: t-Test Two-Sample Assuming Unequal Variances (France vs Germany order values)
A3: France | B3: Germany | D3: t-Test: Two-Sample Assuming Unequal Variances | E3: France | F3: Germany
A4: 26.93 | B4: 178.6 | D4: Mean | E4: =AVERAGE(A4:A37) -> 176.14618 | F4: =AVERAGE(B4:B50) -> 775.88957
A5: 109.25 | B5: 173.23 | D5: Variance | E5: =VAR(A4:A37) -> 109462.56 | F5: =VAR(B4:B50) -> 3556818.5
A6: 256.62 | B6: 18.9 | D6: Observations | E6: =COUNT(A4:A37) -> 34 | F6: =COUNT(B4:B50) -> 47
A7: 5.42 | B7: 28.86 | D7: Hypothesized Mean Difference | E7: 0
A8: 994.83 | B8: 54.54 | D8: df | E8: =ROUND((E5/E6+F5/F6)^2/((E5/E6)^2/(E6-1)+(F5/F6)^2/(F6-1)),0) -> 50
A9: 1743.74 | B9: 8356.81 | D9: t Stat | E9: =(E4-F4-E7)/SQRT(E5/E6+F5/F6) -> -2.1351907
A10: 75.26 | B10: 18.31 | D10: P(T<=t) two-tail | E10: =TTEST(A4:A37,B4:B50,2,3) -> 0.03768142
A11: 6.63 | B11: 3140.61 | D11: Significance level (alpha) | E11: 0.05
A12: 24.21 | B12: 36.99 | D12: t Critical two-tail | E12: =TINV(E11,E8) -> 2.0085591
A13: 300.07 | B13: 6301.44
A14: 45.36 | B14: 236.56 | D14: Decision | E14: =IF(E10<E11,"Significant difference (reject H0)","Not significant (fail to reject H0)") -> Significant difference (reject H0)
A15: 18.2 | B15: 59.71
A16: 281.01 | B16: 428.83 | D16: Order values are copied from Task3_Order_Value (France and Germany invoices). Hypothesis: H0 means are equal; H1 means differ.
A17: 40.36 | B17: 120.98
A18: 129.87 | B18: 26.46
A19: 11.61 | B19: 7150.98
A20: 21.4 | B20: 80.56
A21: 26.33 | B21: 88.53
A22: 37.68 | B22: 58.17
A23: 160.7 | B23: 153.62
A24: 42.24 | B24: 172.12
A25: 351.9 | B25: 319.4
A26: 64.04 | B26: 4274.88
A27: 65.56 | B27: 181.61
A28: 43.74 | B28: 805.56
... A37: 66.13 | B37: 78.12
B38: 7.26
B39: 87.21
B40: 226.14
B41: 87.17
B42: 85.17
B43: 195.84
B44: 18.18
B45: 193.13
B46: 380.63
B47: 170.23
B48: 118.75
B49: 124.13
...

Sheet Insights
A1: Insights: key customer purchasing patterns
A3: Prompt given to the AI tool
A4: I analysed an e-commerce dataset (Online Retail). Facts: total sales {X}; top 3 countries by sales are {A}, {B}, {C} with shares {..}; average order value {..} and median {..}; {n} invoices above 10,000; sales peak in {month}; Sep-Nov accounts for {..}% of sales; France vs Germany order value t-test p = {..}. Write a short summary of the key purchasing patterns and business recommendations.
A6: AI summary (EXAMPLE written from the simulated stand-in data - replace the numbers with your real results)
A7: 1. High-value countries: the United Kingdom produces about 66% of sales, followed by Germany (15%) and EIRE (6%). Sales are concentrated in a few markets, so protecting UK and Germany customers matters most, while smaller markets such as Australia and the Netherlands show room to grow.
A8: 2. Order size: the average order value is about 436, but the median is only about 80. A few very large wholesale-style orders (3 invoices above 10,000, about 11% of all sales) pull the average up, so the average alone overstates a typical order.
A9: 3. Market differences: Germany's average order (about 776) is much larger than France's (about 176), and a two-sample t-test shows this difference is statistically significant (p = 0.038 < 0.05). Germany looks like a bulk-buying market, France like a small-basket market.
A10: 4. Seasonality: sales are about 27% in September to November against 25% for an even spread, pointing to a pre-Christmas build-up. Stock and marketing for gift items should start in early autumn.
A11: 5. Recommendation: offer volume discounts and dedicated account management to bulk buyers, run basket-building offers (bundles, free-shipping thresholds) for low-value markets, and prepare inventory for the autumn peak.
